Workbook

Sheet store_performance-Original Data
A1: store_id | B1: month | C1: region | D1: store_type | E1: marketing_spend | F1: footfall | G1: avg_discount_pct | H1: staff_count | I1: inventory_availability_pct | J1: competitor_distance_km | K1: holiday_flag | L1: customer_rating | M1: monthly_sales | N1: monthly_profit
A2: STR-1001 | B2: 45658 | C2: East | D2: Residential | E2: 70389.11 | F2: 8302 | G2: 0.042 | H2: 17 | I2: 75 | J2: 5.28 | K2: 1 | L2: 3.1 | M2: 658832.62 | N2: 84349.93
A3: STR-1001 | B3: 45689 | C3: East | D3: Residential | E3: 43827.89 | F3: 8487 | G3: 0.168 | H3: 23 | I3: 84.4 | J3: 4.31 | K3: 0 | L3: 2.8 | M3: 634436 | N3: 106130.54
A4: STR-1001 | B4: 45717 | C4: East | D4: Residential | E4: 59921.75 | F4: 9113 | G4: 0.133 | H4: 20 | I4: 88 | J4: 12 | K4: 0 | L4: 3.2 | M4: 678722.06 | N4: 101883.86
A5: STR-1001 | B5: 45748 | C5: East | D5: Residential | E5: 56856.63 | F5: 9431 | G5: 0.142 | H5: 23 | I5: 86.9 | J5: 4.97 | K5: 0 | L5: 3.4 | M5: 658920.3 | N5: 97910.37
A6: STR-1002 | B6: 45658 | C6: East | D6: High Street | E6: 48412.64 | F6: 9545 | G6: 0.231 | H6: 21 | I6: 97.6 | J6: 6.94 | K6: 1 | L6: 4.2 | M6: 741341.44 | N6: 119208.17
A7: STR-1002 | B7: 45689 | C7: East | D7: High Street | E7: 64811.21 | F7: 9792 | G7: 0.112 | H7: 20 | I7: 84.2 | J7: 2.88 | K7: 0 | L7: 4.2 | M7: 761835.34 | N7: 149602.23
A8: STR-1002 | B8: 45717 | C8: East | D8: High Street | E8: 46213.45 | F8: 10616 | G8: 0.122 | H8: 22 | I8: 85.2 | J8: 0.2 | K8: 1 | L8: 4.1 | M8: 806615.54 | N8: 131364.62
A9: STR-1002 | B9: 45748 | C9: East | D9: High Street | E9: 68148.52 | F9: 8567 | G9: 0.127 | H9: 23 | I9: 95.6 | J9: 0.8 | K9: 0 | L9: 3.9 | M9: 850164.26 | N9: 149262.75
A10: STR-1003 | B10: 45658 | C10: North | D10: Airport | E10: 71838.86 | F10: 10979 | G10: 0.215 | H10: 26 | I10: 88.6 | J10: 7.7 | K10: 1 | L10: 3.8 | M10: 930581.7 | N10: 136207.98
A11: STR-1003 | B11: 45689 | C11: North | D11: Airport | E11: 68133.44 | F11: 9459 | G11: 0.22 | H11: 21 | I11: 85 | J11: 1.91 | K11: 0 | L11: 4.2 | M11: 779010.94 | N11: 106328.09
A12: STR-1003 | B12: 45717 | C12: North | D12: Airport | E12: 34285.21 | F12: 9172 | G12: 0.213 | H12: 22 | I12: 88.3 | J12: 10.46 | K12: 1 | L12: 3.8 | M12: 723060.76 | N12: 123131.24
A13: STR-1003 | B13: 45748 | C13: North | D13: Airport | E13: 67979.88 | F13: 11230 | G13: 0.002 | H13: 28 | I13: 85.3 | J13: 7.16 | K13: 0 | L13: 3.8 | M13: 910791.94 | N13: 158891.28
... A34: STR-1009 | B34: 45658 | C34: North | D34: Residential | E34: 54597.83 | F34: 9429 | G34: 0.188 | H34: 21 | I34: 83.3 | J34: 11.71 | K34: 0 | L34: 4.2 | M34: 641865.03 | N34: 81342.58
A35: STR-1009 | B35: 45689 | C35: North | D35: Residential | E35: 73771.91 | F35: 11695 | G35: 0.07 | H35: 25 | I35: 84.7 | J35: 0.62 | K35: 0 | M35: 799477.76 | N35: 164974.41
A36: STR-1009 | B36: 45717 | C36: North | D36: Residential | E36: 74413.88 | F36: 9449 | G36: 0.039 | H36: 23 | I36: 92.1 | J36: 2.12 | K36: 0 | L36: 3.5 | M36: 798952.17 | N36: 161499.04
A37: STR-1009 | B37: 45748 | C37: North | D37: Residential | E37: 52483.77 | F37: 10453 | G37: 0.247 | H37: 25 | I37: 99 | J37: 6.31 | K37: 0 | L37: 3.6 | M37: 800979.78 | N37: 149242.27
A38: STR-1010 | B38: 45658 | C38: North | D38: Mall | E38: 75269.87 | F38: 8838 | G38: 0.092 | H38: 21 | I38: 83.1 | J38: 9.56 | K38: 1 | L38: 4.2 | M38: 820593.93 | N38: 115860.06
A39: STR-1010 | B39: 45689 | C39: North | D39: Mall | E39: 61245.41 | F39: 8156 | G39: 0.156 | H39: 19 | I39: 92.9 | J39: 9.05 | K39: 0 | L39: 3.8 | M39: 718330.53 | N39: 93247.9
A40: STR-1010 | B40: 45717 | C40: North | D40: Mall | E40: 93381.26 | F40: 7562 | G40: 0.198 | H40: 19 | I40: 82.9 | J40: 5.05 | K40: 0 | L40: 4 | M40: 736633.4 | N40: 115654.66
A41: STR-1010 | B41: 45748 | C41: North | D41: Mall | E41: 65012.19 | F41: 9598 | G41: 0.085 | H41: 24 | I41: 98.3 | J41: 0.89 | K41: 0 | L41: 3.8 | M41: 828623.85 | N41: 167320.52
A42: STR-1011 | B42: 45658 | C42: East | D42: Mall | E42: 40462.94 | F42: 3660 | G42: 0.218 | H42: 11 | I42: 95.2 | J42: 5.57 | K42: 0 | L42: 4.4 | M42: 592195.85 | N42: 92291.56
A43: STR-1011 | B43: 45689 | C43: East | D43: Mall | E43: 46123.88 | F43: 3227 | G43: 0.143 | H43: 10 | I43: 75.4 | J43: 1.06 | K43: 0 | L43: 4.4 | M43: 532644.46 | N43: 60681.32
A44: STR-1011 | B44: 45717 | C44: East | D44: Mall | E44: 68077.54 | F44: 3360 | G44: 0.128 | H44: 14 | I44: 88.2 | J44: 1.24 | K44: 1 | L44: 4 | M44: 657429.18 | N44: 88919.74
A45: STR-1011 | B45: 45748 | C45: East | D45: Mall | E45: 64882.14 | F45: 3642 | G45: 0.019 | H45: 13 | I45: 87.8 | J45: 4.52 | K45: 0 | L45: 4.2 | M45: 605178 | N45: 106958.74
A46: STR-1012 | B46: 45658 | C46: West | D46: Residential | E46: 138855.51 | F46: 5145 | G46: 0.06 | H46: 17 | I46: 88.2 | J46: 9.58 | K46: 0 | L46: 3.2 | M46: 595467.6 | N46: 104276.46
A47: STR-1012 | B47: 45689 | C47: West | D47: Residential | E47: 63630.21 | F47: 4460 | G47: 0.235 | H47: 14 | I47: 98.6 | J47: 5.52 | K47: 0 | L47: 3.5 | M47: 599603.4 | N47: 112685.12
... A72: STR-1018 | B72: 45717 | C72: East | D72: High Street | E72: 60571.82 | F72: 3193 | G72: 0.197 | H72: 7 | I72: 99 | J72: 1.43 | K72: 0 | L72: 3.2 | M72: 605023.87 | N72: 98545.81
A73: STR-1018 | B73: 45748 | C73: East | D73: High Street | E73: 55081.16 | F73: 5485 | G73: 0.036 | H73: 12 | I73: 88 | K73: 0 | L73: 3.5 | M73: 674774.09 | N73: 141917.59
A74: STR-1019 | B74: 45658 | C74: East | D74: Residential | E74: 46201.46 | F74: 5918 | G74: 0.277 | H74: 13 | I74: 78.8 | J74: 4.91 | K74: 0 | L74: 4.5 | M74: 616069.41 | N74: 54453.99
A75: STR-1019 | B75: 45689 | C75: East | D75: Residential | E75: 53762.92 | F75: 6821 | G75: 0.066 | H75: 19 | I75: 94.6 | J75: 7.03 | K75: 0 | L75: 4.4 | M75: 630829.94 | N75: 117090.02
A76: STR-1019 | B76: 45717 | C76: East | D76: Residential | E76: 70144.78 | F76: 6806 | G76: 0.178 | H76: 20 | I76: 93.1 | J76: 0.28 | K76: 1 | L76: 4.3 | M76: 788087.68 | N76: 116803.42
A77: STR-1019 | B77: 45748 | C77: East | D77: Residential | E77: 58749.63 | F77: 8252 | G77: 0.203 | H77: 20 | I77: 85.2 | J77: 3.61 | K77: 0 | L77: 4.5 | M77: 680840.36 | N77: 68007.68
A78: STR-1020 | B78: 45658 | C78: South | D78: High Street | E78: 56973.18 | F78: 6662 | G78: 0.1 | H78: 15 | I78: 77.7 | J78: 7.52 | K78: 1 | L78: 3.2 | M78: 643657.47 | N78: 87022.45
A79: STR-1020 | B79: 45689 | C79: South | D79: High Street | E79: 54872.82 | F79: 5962 | G79: 0.064 | H79: 12 | I79: 85.4 | J79: 2.58 | K79: 0 | L79: 2.9 | M79: 691112.6 | N79: 109212.83
A80: STR-1020 | B80: 45717 | C80: South | D80: High Street | E80: 80562.81 | F80: 7470 | G80: 0.172 | H80: 16 | I80: 83.5 | J80: 2.29 | K80: 0 | L80: 3.3 | M80: 776922.17 | N80: 150701.93
A81: STR-1020 | B81: 45748 | C81: South | D81: High Street | E81: 77999.9 | F81: 5974 | G81: 0.252 | H81: 14 | I81: 81.3 | J81: 2.39 | K81: 0 | L81: 3.2 | M81: 636561.34 | N81: 93861.06
A82: STR-1021 | B82: 45658 | C82: West | D82: Mall | E82: 60881.01 | F82: 5410 | G82: 0.179 | H82: 15 | I82: 83.9 | J82: 5.24 | K82: 0 | L82: 4.6 | M82: 621369.58 | N82: 85493.64
A83: STR-1021 | B83: 45689 | C83: West | D83: Mall | E83: 60628.38 | F83: 4451 | G83: 0.095 | H83: 10 | I83: 89.6 | J83: 3.17 | K83: 0 | L83: 4.6 | M83: 682208.01 | N83: 110318.84
A84: STR-1021 | B84: 45717 | C84: West | D84: Mall | E84: 72731.14 | F84: 4644 | G84: 0.084 | H84: 15 | I84: 87.1 | J84: 2.66 | K84: 0 | L84: 4.6 | M84: 727241.86 | N84: 155810.3
...

Sheet Cleaned Data
A1: store_id | B1: month | C1: region | D1: store_type | E1: marketing_spend | F1: footfall | G1: avg_discount_pct | H1: staff_count | I1: inventory_availability_pct | J1: competitor_distance_km | K1: holiday_flag | L1: customer_rating | M1: monthly_sales | N1: monthly_profit | P1: =AVERAGE(J2:J321) -> 4.5590625 | Q1: competitor_distance avg
A2: STR-1001 | B2: 45658 | C2: East | D2: Residential | E2: 70389.11 | F2: 8302 | G2: 0.042 | H2: 17 | I2: 75 | J2: 5.28 | K2: 1 | L2: 3.1 | M2: 658832.62 | N2: 84349.93 | P2: =AVERAGE(L2:L321) -> 3.9245625 | Q2: customer_rating avg
A3: STR-1001 | B3: 45689 | C3: East | D3: Residential | E3: 43827.89 | F3: 8487 | G3: 0.168 | H3: 23 | I3: 84.4 | J3: 4.31 | K3: 0 | L3: 2.8 | M3: 634436 | N3: 106130.54 | P3: =COUNTA(J2:J321) -> 320 | Q3: Count of competitor_distance rows
A4: STR-1001 | B4: 45717 | C4: East | D4: Residential | E4: 59921.75 | F4: 9113 | G4: 0.133 | H4: 20 | I4: 88 | J4: 12 | K4: 0 | L4: 3.2 | M4: 678722.06 | N4: 101883.86 | P4: =COUNTA(L2:L321) -> 320 | Q4: Count of customer_rating rows
A5: STR-1001 | B5: 45748 | C5: East | D5: Residential | E5: 56856.63 | F5: 9431 | G5: 0.142 | H5: 23 | I5: 86.9 | J5: 4.97 | K5: 0 | L5: 3.4 | M5: 658920.3 | N5: 97910.37
A6: STR-1002 | B6: 45658 | C6: East | D6: High Street | E6: 48412.64 | F6: 9545 | G6: 0.231 | H6: 21 | I6: 97.6 | J6: 6.94 | K6: 1 | L6: 4.2 | M6: 741341.44 | N6: 119208.17
A7: STR-1002 | B7: 45689 | C7: East | D7: High Street | E7: 64811.21 | F7: 9792 | G7: 0.112 | H7: 20 | I7: 84.2 | J7: 2.88 | K7: 0 | L7: 4.2 | M7: 761835.34 | N7: 149602.23 | P7: === DATA SUMMARY ===
A8: STR-1002 | B8: 45717 | C8: East | D8: High Street | E8: 46213.45 | F8: 10616 | G8: 0.122 | H8: 22 | I8: 85.2 | J8: 0.2 | K8: 1 | L8: 4.1 | M8: 806615.54 | N8: 131364.62 | P8: CORRELATION WITH MONTHLY_SALES
A9: STR-1002 | B9: 45748 | C9: East | D9: High Street | E9: 68148.52 | F9: 8567 | G9: 0.127 | H9: 23 | I9: 95.6 | J9: 0.8 | K9: 0 | L9: 3.9 | M9: 850164.26 | N9: 149262.75 | P9: marketing_spend | Q9: =CORREL(E2:E321,M2:M321) -> 0.40895561
A10: STR-1003 | B10: 45658 | C10: North | D10: Airport | E10: 71838.86 | F10: 10979 | G10: 0.215 | H10: 26 | I10: 88.6 | J10: 7.7 | K10: 1 | L10: 3.8 | M10: 930581.7 | N10: 136207.98 | P10: footfall | Q10: =CORREL(F2:F321,M2:M321) -> 0.85807071
A11: STR-1003 | B11: 45689 | C11: North | D11: Airport | E11: 68133.44 | F11: 9459 | G11: 0.22 | H11: 21 | I11: 85 | J11: 1.91 | K11: 0 | L11: 4.2 | M11: 779010.94 | N11: 106328.09 | P11: avg_discount_pct | Q11: =CORREL(G2:G321,M2:M321) -> -0.091052199
A12: STR-1003 | B12: 45717 | C12: North | D12: Airport | E12: 34285.21 | F12: 9172 | G12: 0.213 | H12: 22 | I12: 88.3 | J12: 10.46 | K12: 1 | L12: 3.8 | M12: 723060.76 | N12: 123131.24 | P12: staff_count | Q12: =CORREL(H2:H321,M2:M321) -> 0.807645
A13: STR-1003 | B13: 45748 | C13: North | D13: Airport | E13: 67979.88 | F13: 11230 | G13: 0.002 | H13: 28 | I13: 85.3 | J13: 7.16 | K13: 0 | L13: 3.8 | M13: 910791.94 | N13: 158891.28 | P13: inventory_availability_pct | Q13: =CORREL(I2:I321,M2:M321) -> 0.11452081
A14: STR-1004 | B14: 45658 | C14: East | D14: Residential | E14: 71828.26 | F14: 12775 | G14: 0.116 | H14: 30 | I14: 81.7 | J14: 4.24 | K14: 1 | L14: 4.2 | M14: 922168.6 | N14: 107494.53 | P14: competitor_distance_km | Q14: =CORREL(J2:J321,M2:M321) -> -0.10931541
A15: STR-1004 | B15: 45689 | C15: East | D15: Residential | E15: 55716.82 | F15: 10054 | G15: 0.146 | H15: 24 | I15: 84.9 | J15: 1.06 | K15: 0 | L15: 4.3 | M15: 726606.28 | N15: 122729.29 | P15: holiday_flag | Q15: =CORREL(K2:K321,M2:M321) -> 0.19526539
A16: STR-1004 | B16: 45717 | C16: East | D16: Residential | E16: 59909.51 | F16: 8895 | G16: 0.228 | H16: 23 | I16: 88.8 | J16: 0.27 | K16: 0 | L16: 4.3 | M16: 746501.09 | N16: 136816.72 | P16: customer_rating | Q16: =CORREL(L2:L321,M2:M321) -> -0.027081837
A17: STR-1004 | B17: 45748 | C17: East | D17: Residential | E17: 75305.71 | F17: 10940 | G17: 0.006 | H17: 26 | I17: 76.5 | J17: 1.32 | K17: 0 | L17: 4.5 | M17: 834017.02 | N17: 114745.03
A18: STR-1005 | B18: 45658 | C18: South | D18: Residential | E18: 48804.22 | F18: 7057 | G18: 0.005 | H18: 15 | I18: 87.7 | J18: 1.22 | K18: 0 | L18: 3.7 | M18: 666152.52 | N18: 107490.58
A19: STR-1005 | B19: 45689 | C19: South | D19: Residential | E19: 59117.9 | F19: 4263 | G19: 0.119 | H19: 9 | I19: 87.6 | J19: 4.01 | K19: 0 | L19: 3.6 | M19: 573155.19 | N19: 83680.75
A20: STR-1005 | B20: 45717 | C20: South | D20: Residential | E20: 78831.12 | F20: 5538 | G20: 0 | H20: 15 | I20: 94.1 | J20: 0.2 | K20: 0 | L20: 3.9 | M20: 666573.2 | N20: 140641.02
A21: STR-1005 | B21: 45748 | C21: South | D21: Residential | E21: 41441.93 | F21: 4865 | G21: 0.158 | H21: 16 | I21: 88.3 | J21: 0.5 | K21: 0 | L21: 4 | M21: 591619.95 | N21: 99521.35
A22: STR-1006 | B22: 45658 | C22: North | D22: Residential | E22: 30356.28 | F22: 2822 | G22: 0.231 | H22: 9 | I22: 84.8 | J22: 6.95 | K22: 0 | L22: 5 | M22: 415721.82 | N22: 61179.15
A23: STR-1006 | B23: 45689 | C23: North | D23: Residential | E23: 33518.88 | F23: 2121 | G23: 0.176 | H23: 8 | I23: 88.5 | J23: 0.2 | K23: 0 | L23: 5 | M23: 491905.13 | N23: 79212.26
A24: STR-1006 | B24: 45717 | C24: North | D24: Residential | E24: 42267.37 | F24: 3364 | G24: 0.16 | H24: 13 | I24: 82 | J24: 1.61 | K24: 1 | L24: 4.6 | M24: 555929.4 | N24: 115201.76
A25: STR-1006 | B25: 45748 | C25: North | D25: Residential | E25: 62060.43 | F25: 2613 | G25: 0.216 | H25: 12 | I25: 92.1 | J25: 1.55 | K25: 0 | L25: 4.7 | M25: 565810.99 | N25: 77825.46
A26: STR-1007 | B26: 45658 | C26: West | D26: Mall | E26: 57696.69 | F26: 10218 | G26: 0.121 | H26: 25 | I26: 94.8 | J26: 2.99 | K26: 0 | L26: 3.5 | M26: 811771.14 | N26: 148756.24
A27: STR-1007 | B27: 45689 | C27: West | D27: Mall | E27: 172415.52 | F27: 8927 | G27: 0.14 | H27: 22 | I27: 86.2 | J27: 7.04 | K27: 0 | L27: 3.9 | M27: 800451.94 | N27: 111572.29
A28: STR-1007 | B28: 45717 | C28: West | D28: Mall | E28: 55270.52 | F28: 9315 | G28: 0.169 | H28: 23 | I28: 91.9 | J28: 4.94 | K28: 0 | L28: 4 | M28: 783672.82 | N28: 112577.14
... A321: STR-1080 | B321: 45748 | C321: East | D321: Residential | E321: 40553.11 | F321: 5317 | G321: 0.165 | H321: 17 | I321: 84.3 | J321: 11.82 | K321: 0 | L321: 4.1 | M321: 559660.84 | N321: 71443.61

Sheet Dummy Variables
A1: store_id | B1: month | C1: region | D1: store_type | E1: marketing_spend | F1: footfall | G1: avg_discount_pct | H1: staff_count | I1: inventory_availability_pct | J1: competitor_distance_km | K1: holiday_flag | L1: customer_rating | M1: monthly_sales | N1: monthly_profit | O1: region_North | P1: region_South | Q1: region_West | R1: store_High Street | S1: store_Mall | T1: store_Residential
A2: STR-1001 | B2: 45658 | C2: East | D2: Residential | E2: 70389.11 | F2: 8302 | G2: 0.042 | H2: 17 | I2: 75 | J2: 5.28 | K2: 1 | L2: 3.1 | M2: 658832.62 | N2: 84349.93 | O2: =IF(C2="North",1,0) -> 0 | P2: =IF(C2="South",1,0) -> 0 | Q2: =IF(C2="West",1,0) -> 0 | R2: =IF(D2="High Street",1,0) -> 0 | S2: =IF(D2="Mall",1,0) -> 0 | T2: =IF(D2="Residential",1,0) -> 1
A3: STR-1001 | B3: 45689 | C3: East | D3: Residential | E3: 43827.89 | F3: 8487 | G3: 0.168 | H3: 23 | I3: 84.4 | J3: 4.31 | K3: 0 | L3: 2.8 | M3: 634436 | N3: 106130.54 | O3: =IF(C3="North",1,0) -> 0 | P3: =IF(C3="South",1,0) -> 0 | Q3: =IF(C3="West",1,0) -> 0 | R3: =IF(D3="High Street",1,0) -> 0 | S3: =IF(D3="Mall",1,0) -> 0 | T3: =IF(D3="Residential",1,0) -> 1
A4: STR-1001 | B4: 45717 | C4: East | D4: Residential | E4: 59921.75 | F4: 9113 | G4: 0.133 | H4: 20 | I4: 88 | J4: 12 | K4: 0 | L4: 3.2 | M4: 678722.06 | N4: 101883.86 | O4: =IF(C4="North",1,0) -> 0 | P4: =IF(C4="South",1,0) -> 0 | Q4: =IF(C4="West",1,0) -> 0 | R4: =IF(D4="High Street",1,0) -> 0 | S4: =IF(D4="Mall",1,0) -> 0 | T4: =IF(D4="Residential",1,0) -> 1
A5: STR-1001 | B5: 45748 | C5: East | D5: Residential | E5: 56856.63 | F5: 9431 | G5: 0.142 | H5: 23 | I5: 86.9 | J5: 4.97 | K5: 0 | L5: 3.4 | M5: 658920.3 | N5: 97910.37 | O5: =IF(C5="North",1,0) -> 0 | P5: =IF(C5="South",1,0) -> 0 | Q5: =IF(C5="West",1,0) -> 0 | R5: =IF(D5="High Street",1,0) -> 0 | S5: =IF(D5="Mall",1,0) -> 0 | T5: =IF(D5="Residential",1,0) -> 1
A6: STR-1002 | B6: 45658 | C6: East | D6: High Street | E6: 48412.64 | F6: 9545 | G6: 0.231 | H6: 21 | I6: 97.6 | J6: 6.94 | K6: 1 | L6: 4.2 | M6: 741341.44 | N6: 119208.17 | O6: =IF(C6="North",1,0) -> 0 | P6: =IF(C6="South",1,0) -> 0 | Q6: =IF(C6="West",1,0) -> 0 | R6: =IF(D6="High Street",1,0) -> 1 | S6: =IF(D6="Mall",1,0) -> 0 | T6: =IF(D6="Residential",1,0) -> 0
A7: STR-1002 | B7: 45689 | C7: East | D7: High Street | E7: 64811.21 | F7: 9792 | G7: 0.112 | H7: 20 | I7: 84.2 | J7: 2.88 | K7: 0 | L7: 4.2 | M7: 761835.34 | N7: 149602.23 | O7: =IF(C7="North",1,0) -> 0 | P7: =IF(C7="South",1,0) -> 0 | Q7: =IF(C7="West",1,0) -> 0 | R7: =IF(D7="High Street",1,0) -> 1 | S7: =IF(D7="Mall",1,0) -> 0 | T7: =IF(D7="Residential",1,0) -> 0
A8: STR-1002 | B8: 45717 | C8: East | D8: High Street | E8: 46213.45 | F8: 10616 | G8: 0.122 | H8: 22 | I8: 85.2 | J8: 0.2 | K8: 1 | L8: 4.1 | M8: 806615.54 | N8: 131364.62 | O8: =IF(C8="North",1,0) -> 0 | P8: =IF(C8="South",1,0) -> 0 | Q8: =IF(C8="West",1,0) -> 0 | R8: =IF(D8="High Street",1,0) -> 1 | S8: =IF(D8="Mall",1,0) -> 0 | T8: =IF(D8="Residential",1,0) -> 0
A9: STR-1002 | B9: 45748 | C9: East | D9: High Street | E9: 68148.52 | F9: 8567 | G9: 0.127 | H9: 23 | I9: 95.6 | J9: 0.8 | K9: 0 | L9: 3.9 | M9: 850164.26 | N9: 149262.75 | O9: =IF(C9="North",1,0) -> 0 | P9: =IF(C9="South",1,0) -> 0 | Q9: =IF(C9="West",1,0) -> 0 | R9: =IF(D9="High Street",1,0) -> 1 | S9: =IF(D9="Mall",1,0) -> 0 | T9: =IF(D9="Residential",1,0) -> 0
A10: STR-1003 | B10: 45658 | C10: North | D10: Airport | E10: 71838.86 | F10: 10979 | G10: 0.215 | H10: 26 | I10: 88.6 | J10: 7.7 | K10: 1 | L10: 3.8 | M10: 930581.7 | N10: 136207.98 | O10: =IF(C10="North",1,0) -> 1 | P10: =IF(C10="South",1,0) -> 0 | Q10: =IF(C10="West",1,0) -> 0 | R10: =IF(D10="High Street",1,0) -> 0 | S10: =IF(D10="Mall",1,0) -> 0 | T10: =IF(D10="Residential",1,0) -> 0
A11: STR-1003 | B11: 45689 | C11: North | D11: Airport | E11: 68133.44 | F11: 9459 | G11: 0.22 | H11: 21 | I11: 85 | J11: 1.91 | K11: 0 | L11: 4.2 | M11: 779010.94 | N11: 106328.09 | O11: =IF(C11="North",1,0) -> 1 | P11: =IF(C11="South",1,0) -> 0 | Q11: =IF(C11="West",1,0) -> 0 | R11: =IF(D11="High Street",1,0) -> 0 | S11: =IF(D11="Mall",1,0) -> 0 | T11: =IF(D11="Residential",1,0) -> 0
A12: STR-1003 | B12: 45717 | C12: North | D12: Airport | E12: 34285.21 | F12: 9172 | G12: 0.213 | H12: 22 | I12: 88.3 | J12: 10.46 | K12: 1 | L12: 3.8 | M12: 723060.76 | N12: 123131.24 | O12: =IF(C12="North",1,0) -> 1 | P12: =IF(C12="South",1,0) -> 0 | Q12: =IF(C12="West",1,0) -> 0 | R12: =IF(D12="High Street",1,0) -> 0 | S12: =IF(D12="Mall",1,0) -> 0 | T12: =IF(D12="Residential",1,0) -> 0
A13: STR-1003 | B13: 45748 | C13: North | D13: Airport | E13: 67979.88 | F13: 11230 | G13: 0.002 | H13: 28 | I13: 85.3 | J13: 7.16 | K13: 0 | L13: 3.8 | M13: 910791.94 | N13: 158891.28 | O13: =IF(C13="North",1,0) -> 1 | P13: =IF(C13="South",1,0) -> 0 | Q13: =IF(C13="West",1,0) -> 0 | R13: =IF(D13="High Street",1,0) -> 0 | S13: =IF(D13="Mall",1,0) -> 0 | T13: =IF(D13="Residential",1,0) -> 0
... A321: STR-1080 | B321: 45748 | C321: East | D321: Residential | E321: 40553.11 | F321: 5317 | G321: 0.165 | H321: 17 | I321: 84.3 | J321: 11.82 | K321: 0 | L321: 4.1 | M321: 559660.84 | N321: 71443.61 | O321: =IF(C321="North",1,0) -> 0 | P321: =IF(C321="South",1,0) -> 0 | Q321: =IF(C321="West",1,0) -> 0 | R321: =IF(D321="High Street",1,0) -> 0 | S321: =IF(D321="Mall",1,0) -> 0 | T321: =IF(D321="Residential",1,0) -> 1

Sheet Simple Regression
A1: MODEL 1: Simple Regression — monthly_sales vs footfall
A3: SUMMARY OUTPUT
A5: Regression Statistics
A6: Multiple R | B6: 0.85807071
A7: R Square | B7: 0.73628534
A8: Adjusted R Square | B8: 0.73545605
A9: Standard Error | B9: 53373.736
A10: Observations | B10: 320
A12: ANOVA
B13: df | C13: SS | D13: MS | E13: F | F13: Significance F
A14: Regression | B14: 1 | C14: 2.5292643e+12 | D14: 2.5292643e+12 | E14: 887.84878 | F14: 4.7503615e-94
A15: Residual | B15: 318 | C15: 9.0590432e+11 | D15: 2.8487557e+09
A16: Total | B16: 319 | C16: 3.4351686e+12
B18: Coefficients | C18: Standard Error | D18: t Stat | E18: P-value | F18: Lower 95% | G18: Upper 95% | H18: Lower 95.0% | I18: Upper 95.0%
A19: Intercept | B19: 446410.58 | C19: 8407.7383 | D19: 53.095205 | E19: 4.0862696e-160 | F19: 429868.76 | G19: 462952.4 | H19: 429868.76 | I19: 462952.4
A20: footfall | B20: 35.678031 | C20: 1.1973783 | D20: 29.796791 | E20: 4.7503615e-94 | F20: 33.322247 | G20: 38.033815 | H20: 33.322247 | I20: 38.033815
A23: MODEL 2: Simple Regression — monthly_sales vs marketing_spend
A25: SUMMARY OUTPUT
A27: Regression Statistics
A28: Multiple R | B28: 0.40895561
A29: R Square | B29: 0.16724469
A30: Adjusted R Square | B30: 0.16462596
A31: Standard Error | B31: 94846.034
A32: Observations | B32: 320
A34: ANOVA
B35: df | C35: SS | D35: MS | E35: F | F35: Significance F
A36: Regression | B36: 1 | C36: 5.7451371e+11 | D36: 5.7451371e+11 | E36: 63.864873 | F36: 2.4800615e-14
A37: Residual | B37: 318 | C37: 2.8606549e+12 | D37: 8.9957701e+09
A38: Total | B38: 319 | C38: 3.4351686e+12
B40: Coefficients | C40: Standard Error | D40: t Stat | E40: P-value | F40: Lower 95% | G40: Upper 95% | H40: Lower 95.0% | I40: Upper 95.0%
A41: Intercept | B41: 560777.35 | C41: 15906.906 | D41: 35.253703 | E41: 6.9528769e-112 | F41: 529481.27 | G41: 592073.42 | H41: 529481.27 | I41: 592073.42
A42: marketing_spend | B42: 2.1295753 | C42: 0.26647838 | D42: 7.9915501 | E42: 2.4800615e-14 | F42: 1.6052919 | G42: 2.6538587 | H42: 1.6052919 | I42: 2.6538587

Sheet Multiple Regression
A1: monthly_sales | B1: footfall | C1: staff_count | D1: marketing_spend | E1: holiday_flag | F1: region_North | G1: region_South | H1: region_West
A2: ='Cleaned Data'!M2 -> 658832.62 | B2: ='Cleaned Data'!F2 -> 8302 | C2: ='Cleaned Data'!H2 -> 17 | D2: ='Cleaned Data'!E2 -> 70389.11 | E2: ='Cleaned Data'!K2 -> 1 | F2: ='Dummy Variables'!O2 -> 0 | G2: ='Dummy Variables'!P2 -> 0 | H2: ='Dummy Variables'!Q2 -> 0
A3: ='Cleaned Data'!M3 -> 634436 | B3: ='Cleaned Data'!F3 -> 8487 | C3: ='Cleaned Data'!H3 -> 23 | D3: ='Cleaned Data'!E3 -> 43827.89 | E3: ='Cleaned Data'!K3 -> 0 | F3: ='Dummy Variables'!O3 -> 0 | G3: ='Dummy Variables'!P3 -> 0 | H3: ='Dummy Variables'!Q3 -> 0 | J3: SUMMARY OUTPUT
A4: ='Cleaned Data'!M4 -> 678722.06 | B4: ='Cleaned Data'!F4 -> 9113 | C4: ='Cleaned Data'!H4 -> 20 | D4: ='Cleaned Data'!E4 -> 59921.75 | E4: ='Cleaned Data'!K4 -> 0 | F4: ='Dummy Variables'!O4 -> 0 | G4: ='Dummy Variables'!P4 -> 0 | H4: ='Dummy Variables'!Q4 -> 0
A5: ='Cleaned Data'!M5 -> 658920.3 | B5: ='Cleaned Data'!F5 -> 9431 | C5: ='Cleaned Data'!H5 -> 23 | D5: ='Cleaned Data'!E5 -> 56856.63 | E5: ='Cleaned Data'!K5 -> 0 | F5: ='Dummy Variables'!O5 -> 0 | G5: ='Dummy Variables'!P5 -> 0 | H5: ='Dummy Variables'!Q5 -> 0 | J5: Regression Statistics
A6: ='Cleaned Data'!M6 -> 741341.44 | B6: ='Cleaned Data'!F6 -> 9545 | C6: ='Cleaned Data'!H6 -> 21 | D6: ='Cleaned Data'!E6 -> 48412.64 | E6: ='Cleaned Data'!K6 -> 1 | F6: ='Dummy Variables'!O6 -> 0 | G6: ='Dummy Variables'!P6 -> 0 | H6: ='Dummy Variables'!Q6 -> 0 | J6: Multiple R | K6: 0.8910838
A7: ='Cleaned Data'!M7 -> 761835.34 | B7: ='Cleaned Data'!F7 -> 9792 | C7: ='Cleaned Data'!H7 -> 20 | D7: ='Cleaned Data'!E7 -> 64811.21 | E7: ='Cleaned Data'!K7 -> 0 | F7: ='Dummy Variables'!O7 -> 0 | G7: ='Dummy Variables'!P7 -> 0 | H7: ='Dummy Variables'!Q7 -> 0 | J7: R Square | K7: 0.79403033
A8: ='Cleaned Data'!M8 -> 806615.54 | B8: ='Cleaned Data'!F8 -> 10616 | C8: ='Cleaned Data'!H8 -> 22 | D8: ='Cleaned Data'!E8 -> 46213.45 | E8: ='Cleaned Data'!K8 -> 1 | F8: ='Dummy Variables'!O8 -> 0 | G8: ='Dummy Variables'!P8 -> 0 | H8: ='Dummy Variables'!Q8 -> 0 | J8: Adjusted R Square | K8: 0.78940922
A9: ='Cleaned Data'!M9 -> 850164.26 | B9: ='Cleaned Data'!F9 -> 8567 | C9: ='Cleaned Data'!H9 -> 23 | D9: ='Cleaned Data'!E9 -> 68148.52 | E9: ='Cleaned Data'!K9 -> 0 | F9: ='Dummy Variables'!O9 -> 0 | G9: ='Dummy Variables'!P9 -> 0 | H9: ='Dummy Variables'!Q9 -> 0 | J9: Standard Error | K9: 47620.984
A10: ='Cleaned Data'!M10 -> 930581.7 | B10: ='Cleaned Data'!F10 -> 10979 | C10: ='Cleaned Data'!H10 -> 26 | D10: ='Cleaned Data'!E10 -> 71838.86 | E10: ='Cleaned Data'!K10 -> 1 | F10: ='Dummy Variables'!O10 -> 1 | G10: ='Dummy Variables'!P10 -> 0 | H10: ='Dummy Variables'!Q10 -> 0 | J10: Observations | K10: 320
A11: ='Cleaned Data'!M11 -> 779010.94 | B11: ='Cleaned Data'!F11 -> 9459 | C11: ='Cleaned Data'!H11 -> 21 | D11: ='Cleaned Data'!E11 -> 68133.44 | E11: ='Cleaned Data'!K11 -> 0 | F11: ='Dummy Variables'!O11 -> 1 | G11: ='Dummy Variables'!P11 -> 0 | H11: ='Dummy Variables'!Q11 -> 0
A12: ='Cleaned Data'!M12 -> 723060.76 | B12: ='Cleaned Data'!F12 -> 9172 | C12: ='Cleaned Data'!H12 -> 22 | D12: ='Cleaned Data'!E12 -> 34285.21 | E12: ='Cleaned Data'!K12 -> 1 | F12: ='Dummy Variables'!O12 -> 1 | G12: ='Dummy Variables'!P12 -> 0 | H12: ='Dummy Variables'!Q12 -> 0 | J12: ANOVA
A13: ='Cleaned Data'!M13 -> 910791.94 | B13: ='Cleaned Data'!F13 -> 11230 | C13: ='Cleaned Data'!H13 -> 28 | D13: ='Cleaned Data'!E13 -> 67979.88 | E13: ='Cleaned Data'!K13 -> 0 | F13: ='Dummy Variables'!O13 -> 1 | G13: ='Dummy Variables'!P13 -> 0 | H13: ='Dummy Variables'!Q13 -> 0 | K13: df | L13: SS | M13: MS | N13: F | O13: Significance F
A14: ='Cleaned Data'!M14 -> 922168.6 | B14: ='Cleaned Data'!F14 -> 12775 | C14: ='Cleaned Data'!H14 -> 30 | D14: ='Cleaned Data'!E14 -> 71828.26 | E14: ='Cleaned Data'!K14 -> 1 | F14: ='Dummy Variables'!O14 -> 0 | G14: ='Dummy Variables'!P14 -> 0 | H14: ='Dummy Variables'!Q14 -> 0 | J14: Regression | K14: 7 | L14: 2.7276281e+12 | M14: 3.8966115e+11 | N14: 171.82659 | O14: 4.764701e-103
A15: ='Cleaned Data'!M15 -> 726606.28 | B15: ='Cleaned Data'!F15 -> 10054 | C15: ='Cleaned Data'!H15 -> 24 | D15: ='Cleaned Data'!E15 -> 55716.82 | E15: ='Cleaned Data'!K15 -> 0 | F15: ='Dummy Variables'!O15 -> 0 | G15: ='Dummy Variables'!P15 -> 0 | H15: ='Dummy Variables'!Q15 -> 0 | J15: Residual | K15: 312 | L15: 7.0754055e+11 | M15: 2.2677582e+09
A16: ='Cleaned Data'!M16 -> 746501.09 | B16: ='Cleaned Data'!F16 -> 8895 | C16: ='Cleaned Data'!H16 -> 23 | D16: ='Cleaned Data'!E16 -> 59909.51 | E16: ='Cleaned Data'!K16 -> 0 | F16: ='Dummy Variables'!O16 -> 0 | G16: ='Dummy Variables'!P16 -> 0 | H16: ='Dummy Variables'!Q16 -> 0 | J16: Total | K16: 319 | L16: 3.4351686e+12
A17: ='Cleaned Data'!M17 -> 834017.02 | B17: ='Cleaned Data'!F17 -> 10940 | C17: ='Cleaned Data'!H17 -> 26 | D17: ='Cleaned Data'!E17 -> 75305.71 | E17: ='Cleaned Data'!K17 -> 0 | F17: ='Dummy Variables'!O17 -> 0 | G17: ='Dummy Variables'!P17 -> 0 | H17: ='Dummy Variables'!Q17 -> 0
A18: ='Cleaned Data'!M18 -> 666152.52 | B18: ='Cleaned Data'!F18 -> 7057 | C18: ='Cleaned Data'!H18 -> 15 | D18: ='Cleaned Data'!E18 -> 48804.22 | E18: ='Cleaned Data'!K18 -> 0 | F18: ='Dummy Variables'!O18 -> 0 | G18: ='Dummy Variables'!P18 -> 1 | H18: ='Dummy Variables'!Q18 -> 0 | K18: Coefficients | L18: Standard Error | M18: t Stat | N18: P-value | O18: Lower 95% | P18: Upper 95% | Q18: Lower 95.0% | R18: Upper 95.0%
A19: ='Cleaned Data'!M19 -> 573155.19 | B19: ='Cleaned Data'!F19 -> 4263 | C19: ='Cleaned Data'!H19 -> 9 | D19: ='Cleaned Data'!E19 -> 59117.9 | E19: ='Cleaned Data'!K19 -> 0 | F19: ='Dummy Variables'!O19 -> 0 | G19: ='Dummy Variables'!P19 -> 1 | H19: ='Dummy Variables'!Q19 -> 0 | J19: Intercept | K19: 370748.28 | L19: 12219.943 | M19: 30.339607 | N19: 4.3978336e-95 | O19: 346704.36 | P19: 394792.19 | Q19: 346704.36 | R19: 394792.19
A20: ='Cleaned Data'!M20 -> 666573.2 | B20: ='Cleaned Data'!F20 -> 5538 | C20: ='Cleaned Data'!H20 -> 15 | D20: ='Cleaned Data'!E20 -> 78831.12 | E20: ='Cleaned Data'!K20 -> 0 | F20: ='Dummy Variables'!O20 -> 0 | G20: ='Dummy Variables'!P20 -> 1 | H20: ='Dummy Variables'!Q20 -> 0 | J20: footfall | K20: 29.298876 | L20: 2.7271315 | M20: 10.743478 | N20: 4.0694096e-23 | O20: 23.932982 | P20: 34.66477 | Q20: 23.932982 | R20: 34.66477
A21: ='Cleaned Data'!M21 -> 591619.95 | B21: ='Cleaned Data'!F21 -> 4865 | C21: ='Cleaned Data'!H21 -> 16 | D21: ='Cleaned Data'!E21 -> 41441.93 | E21: ='Cleaned Data'!K21 -> 0 | F21: ='Dummy Variables'!O21 -> 0 | G21: ='Dummy Variables'!P21 -> 1 | H21: ='Dummy Variables'!Q21 -> 0 | J21: staff_count | K21: 2309.8747 | L21: 1370.1045 | M21: 1.6859113 | N21: 0.0928126 | O21: -385.93813 | P21: 5005.6876 | Q21: -385.93813 | R21: 5005.6876
A22: ='Cleaned Data'!M22 -> 415721.82 | B22: ='Cleaned Data'!F22 -> 2822 | C22: ='Cleaned Data'!H22 -> 9 | D22: ='Cleaned Data'!E22 -> 30356.28 | E22: ='Cleaned Data'!K22 -> 0 | F22: ='Dummy Variables'!O22 -> 1 | G22: ='Dummy Variables'!P22 -> 0 | H22: ='Dummy Variables'!Q22 -> 0 | J22: marketing_spend | K22: 1.136862 | L22: 0.13802245 | M22: 8.2367904 | N22: 4.9201929e-15 | O22: 0.86528948 | P22: 1.4084344 | Q22: 0.86528948 | R22: 1.4084344
A23: ='Cleaned Data'!M23 -> 491905.13 | B23: ='Cleaned Data'!F23 -> 2121 | C23: ='Cleaned Data'!H23 -> 8 | D23: ='Cleaned Data'!E23 -> 33518.88 | E23: ='Cleaned Data'!K23 -> 0 | F23: ='Dummy Variables'!O23 -> 1 | G23: ='Dummy Variables'!P23 -> 0 | H23: ='Dummy Variables'!Q23 -> 0 | J23: holiday_flag | K23: 12258.286 | L23: 7221.925 | M23: 1.6973709 | N23: 0.090623747 | O23: -1951.5488 | P23: 26468.12 | Q23: -1951.5488 | R23: 26468.12
A24: ='Cleaned Data'!M24 -> 555929.4 | B24: ='Cleaned Data'!F24 -> 3364 | C24: ='Cleaned Data'!H24 -> 13 | D24: ='Cleaned Data'!E24 -> 42267.37 | E24: ='Cleaned Data'!K24 -> 1 | F24: ='Dummy Variables'!O24 -> 1 | G24: ='Dummy Variables'!P24 -> 0 | H24: ='Dummy Variables'!Q24 -> 0 | J24: region_North | K24: 12867.025 | L24: 7611.4487 | M24: 1.6904831 | N24: 0.091934309 | O24: -2109.2346 | P24: 27843.285 | Q24: -2109.2346 | R24: 27843.285
A25: ='Cleaned Data'!M25 -> 565810.99 | B25: ='Cleaned Data'!F25 -> 2613 | C25: ='Cleaned Data'!H25 -> 12 | D25: ='Cleaned Data'!E25 -> 62060.43 | E25: ='Cleaned Data'!K25 -> 0 | F25: ='Dummy Variables'!O25 -> 1 | G25: ='Dummy Variables'!P25 -> 0 | H25: ='Dummy Variables'!Q25 -> 0 | J25: region_South | K25: 24466.781 | L25: 7735.4367 | M25: 3.1629475 | N25: 0.0017155151 | O25: 9246.5624 | P25: 39686.999 | Q25: 9246.5624 | R25: 39686.999
A26: ='Cleaned Data'!M26 -> 811771.14 | B26: ='Cleaned Data'!F26 -> 10218 | C26: ='Cleaned Data'!H26 -> 25 | D26: ='Cleaned Data'!E26 -> 57696.69 | E26: ='Cleaned Data'!K26 -> 0 | F26: ='Dummy Variables'!O26 -> 0 | G26: ='Dummy Variables'!P26 -> 0 | H26: ='Dummy Variables'!Q26 -> 1 | J26: region_West | K26: 21561.447 | L26: 6871.4233 | M26: 3.137843 | N26: 0.0018644602 | O26: 8041.259 | P26: 35081.636 | Q26: 8041.259 | R26: 35081.636
A27: ='Cleaned Data'!M27 -> 800451.94 | B27: ='Cleaned Data'!F27 -> 8927 | C27: ='Cleaned Data'!H27 -> 22 | D27: ='Cleaned Data'!E27 -> 172415.52 | E27: ='Cleaned Data'!K27 -> 0 | F27: ='Dummy Variables'!O27 -> 0 | G27: ='Dummy Variables'!P27 -> 0 | H27: ='Dummy Variables'!Q27 -> 1
A28: ='Cleaned Data'!M28 -> 783672.82 | B28: ='Cleaned Data'!F28 -> 9315 | C28: ='Cleaned Data'!H28 -> 23 | D28: ='Cleaned Data'!E28 -> 55270.52 | E28: ='Cleaned Data'!K28 -> 0 | F28: ='Dummy Variables'!O28 -> 0 | G28: ='Dummy Variables'!P28 -> 0 | H28: ='Dummy Variables'!Q28 -> 1
A29: ='Cleaned Data'!M29 -> 701641.97 | B29: ='Cleaned Data'!F29 -> 7223 | C29: ='Cleaned Data'!H29 -> 16 | D29: ='Cleaned Data'!E29 -> 52715.1 | E29: ='Cleaned Data'!K29 -> 0 | F29: ='Dummy Variables'!O29 -> 0 | G29: ='Dummy Variables'!P29 -> 0 | H29: ='Dummy Variables'!Q29 -> 1
A30: ='Cleaned Data'!M30 -> 511844.41 | B30: ='Cleaned Data'!F30 -> 3988 | C30: ='Cleaned Data'!H30 -> 11 | D30: ='Cleaned Data'!E30 -> 68600.62 | E30: ='Cleaned Data'!K30 -> 0 | F30: ='Dummy Variables'!O30 -> 0 | G30: ='Dummy Variables'!P30 -> 0 | H30: ='Dummy Variables'!Q30 -> 0 | J30: RESIDUAL OUTPUT
A31: ='Cleaned Data'!M31 -> 537383.79 | B31: ='Cleaned Data'!F31 -> 2390 | C31: ='Cleaned Data'!H31 -> 9 | D31: ='Cleaned Data'!E31 -> 63176.73 | E31: ='Cleaned Data'!K31 -> 0 | F31: ='Dummy Variables'!O31 -> 0 | G31: ='Dummy Variables'!P31 -> 0 | H31: ='Dummy Variables'!Q31 -> 0
A32: ='Cleaned Data'!M32 -> 500173.02 | B32: ='Cleaned Data'!F32 -> 2471 | C32: ='Cleaned Data'!H32 -> 11 | D32: ='Cleaned Data'!E32 -> 44970.08 | E32: ='Cleaned Data'!K32 -> 1 | F32: ='Dummy Variables'!O32 -> 0 | G32: ='Dummy Variables'!P32 -> 0 | H32: ='Dummy Variables'!Q32 -> 0 | J32: Observation | K32: Predicted monthly_sales | L32: Residuals
A33: ='Cleaned Data'!M33 -> 427917.38 | B33: ='Cleaned Data'!F33 -> 971 | C33: ='Cleaned Data'!H33 -> 5 | D33: ='Cleaned Data'!E33 -> 69816.35 | E33: ='Cleaned Data'!K33 -> 0 | F33: ='Dummy Variables'!O33 -> 0 | G33: ='Dummy Variables'!P33 -> 0 | H33: ='Dummy Variables'!Q33 -> 0 | J33: 1 | K33: 745536.4 | L33: -86703.784
A34: ='Cleaned Data'!M34 -> 641865.03 | B34: ='Cleaned Data'!F34 -> 9429 | C34: ='Cleaned Data'!H34 -> 21 | D34: ='Cleaned Data'!E34 -> 54597.83 | E34: ='Cleaned Data'!K34 -> 0 | F34: ='Dummy Variables'!O34 -> 1 | G34: ='Dummy Variables'!P34 -> 0 | H34: ='Dummy Variables'!Q34 -> 0 | J34: 2 | K34: 722361.22 | L34: -87925.218
A35: ='Cleaned Data'!M35 -> 799477.76 | B35: ='Cleaned Data'!F35 -> 11695 | C35: ='Cleaned Data'!H35 -> 25 | D35: ='Cleaned Data'!E35 -> 73771.91 | E35: ='Cleaned Data'!K35 -> 0 | F35: ='Dummy Variables'!O35 -> 1 | G35: ='Dummy Variables'!P35 -> 0 | H35: ='Dummy Variables'!Q35 -> 0 | J35: 3 | K35: 752069.19 | L35: -73347.128
A36: ='Cleaned Data'!M36 -> 798952.17 | B36: ='Cleaned Data'!F36 -> 9449 | C36: ='Cleaned Data'!H36 -> 23 | D36: ='Cleaned Data'!E36 -> 74413.88 | E36: ='Cleaned Data'!K36 -> 0 | F36: ='Dummy Variables'!O36 -> 1 | G36: ='Dummy Variables'!P36 -> 0 | H36: ='Dummy Variables'!Q36 -> 0 | J36: 4 | K36: 764831.24 | L36: -105910.94
A37: ='Cleaned Data'!M37 -> 800979.78 | B37: ='Cleaned Data'!F37 -> 10453 | C37: ='Cleaned Data'!H37 -> 25 | D37: ='Cleaned Data'!E37 -> 52483.77 | E37: ='Cleaned Data'!K37 -> 0 | F37: ='Dummy Variables'!O37 -> 1 | G37: ='Dummy Variables'!P37 -> 0 | H37: ='Dummy Variables'!Q37 -> 0 | J37: 5 | K37: 766210.19 | L37: -24868.753
A38: ='Cleaned Data'!M38 -> 820593.93 | B38: ='Cleaned Data'!F38 -> 8838 | C38: ='Cleaned Data'!H38 -> 21 | D38: ='Cleaned Data'!E38 -> 75269.87 | E38: ='Cleaned Data'!K38 -> 1 | F38: ='Dummy Variables'!O38 -> 1 | G38: ='Dummy Variables'!P38 -> 0 | H38: ='Dummy Variables'!Q38 -> 0 | J38: 6 | K38: 777521.77 | L38: -15686.426
A39: ='Cleaned Data'!M39 -> 718330.53 | B39: ='Cleaned Data'!F39 -> 8156 | C39: ='Cleaned Data'!H39 -> 19 | D39: ='Cleaned Data'!E39 -> 61245.41 | E39: ='Cleaned Data'!K39 -> 0 | F39: ='Dummy Variables'!O39 -> 1 | G39: ='Dummy Variables'!P39 -> 0 | H39: ='Dummy Variables'!Q39 -> 0 | J39: 7 | K39: 797398.99 | L39: 9216.5509
A40: ='Cleaned Data'!M40 -> 736633.4 | B40: ='Cleaned Data'!F40 -> 7562 | C40: ='Cleaned Data'!H40 -> 19 | D40: ='Cleaned Data'!E40 -> 93381.26 | E40: ='Cleaned Data'!K40 -> 0 | F40: ='Dummy Variables'!O40 -> 1 | G40: ='Dummy Variables'!P40 -> 0 | H40: ='Dummy Variables'!Q40 -> 0 | J40: 8 | K40: 752354.33 | L40: 97809.932
...

Sheet Model Comparison
A1: MODEL COMPARISON
A3: Model | B3: Model 1 - Simple | C3: Model 2 - Simple | D3: Model 3 - Multiple
A4: Dependent Variable | B4: monthly_sales | C4: monthly_sales | D4: monthly_sales
A5: Independent Variables | B5: footfall | C5: marketing_spend | D5: footfall, staff_count, marketing_spend, holiday_flag, region_North, region_South, region_West
A6: R Square | B6: 0.736 | C6: 0.167 | D6: 0.794
A7: Adjusted R Square | B7: 0.735 | C7: 0.165 | D7: 0.789
A8: Standard Error | B8: 53374 | C8: 94846 | D8: 47621
A9: Observations | B9: 320 | C9: 320 | D9: 320
A10: Significant Variables | B10: footfall | C10: marketing_spend | D10: footfall, marketing_spend, region_South, region_West
A11: Non-Significant Variables | B11: None | C11: None | D11: staff_count, holiday_flag, region_North
A12: P-value (main variable) | B12: 4.7503615e-94 | C12: 2.4800615e-14 | D12: 4.0694096e-23
A13: Business Usefulness | B13: High - footfall strongly predicts sales | C13: Moderate — marketing spend shows positive ROI of 1.14x but weak predictor | D13: Best model — explains 79.4% of sales using multiple factors
A14: Limitation | B14: Only 1 variable - misses other factors | C14: Only explains 16.8% of sales — many other factors missing | D14: Assumes linear relationships — does not capture store size or seasonal trends

Sheet Residual Analysis
A1: RESIDUAL ANALYSIS — Final Model (Multiple Regression)
A3: Observation | B3: Actual Sales | C3: Predicted Sales | D3: Residual | E3: Store_ID | F3: Region | G3: Store Type | I3: TOP 5 LARGEST POSITIVE RESIDUALS
A4: 1 | B4: ='Cleaned Data'!M2 -> 658832.62 | C4: ='Multiple Regression'!K33 -> 745536.4 | D4: ='Multiple Regression'!L33 -> -86703.784 | E4: ='Cleaned Data'!A2 -> STR-1001 | F4: ='Cleaned Data'!C2 -> East | G4: ='Cleaned Data'!D2 -> Residential | I4: Observation | J4: Store_ID | K4: Region | L4: Store Type | M4: Actual Sales | N4: Predicted Sales | O4: Residual
A5: 2 | B5: ='Cleaned Data'!M3 -> 634436 | C5: ='Multiple Regression'!K34 -> 722361.22 | D5: ='Multiple Regression'!L34 -> -87925.218 | E5: ='Cleaned Data'!A3 -> STR-1001 | F5: ='Cleaned Data'!C3 -> East | G5: ='Cleaned Data'!D3 -> Residential | I5: =MATCH(O5,$D$4:$D$323,0) -> 112 | J5: =INDEX($E$4:$E$323,MATCH(O5,$D$4:$D$323,0)) -> STR-1028 | K5: =INDEX($F$4:$F$323,MATCH(O5,$D$4:$D$323,0)) -> East | L5: =INDEX($G$4:$G$323,MATCH(O5,$D$4:$D$323,0)) -> Mall | M5: =INDEX($B$4:$B$323,MATCH(O5,$D$4:$D$323,0)) -> 713611.16 | N5: =INDEX($C$4:$C$323,MATCH(O5,$D$4:$D$323,0)) -> 577486.68 | O5: =LARGE($D$4:$D$323,1) -> 136124.48
A6: 3 | B6: ='Cleaned Data'!M4 -> 678722.06 | C6: ='Multiple Regression'!K35 -> 752069.19 | D6: ='Multiple Regression'!L35 -> -73347.128 | E6: ='Cleaned Data'!A4 -> STR-1001 | F6: ='Cleaned Data'!C4 -> East | G6: ='Cleaned Data'!D4 -> Residential | I6: =MATCH(O6,$D$4:$D$323,0) -> 104 | J6: =INDEX($E$4:$E$323,MATCH(O6,$D$4:$D$323,0)) -> STR-1026 | K6: =INDEX($F$4:$F$323,MATCH(O6,$D$4:$D$323,0)) -> East | L6: =INDEX($G$4:$G$323,MATCH(O6,$D$4:$D$323,0)) -> Mall | M6: =INDEX($B$4:$B$323,MATCH(O6,$D$4:$D$323,0)) -> 625514.04 | N6: =INDEX($C$4:$C$323,MATCH(O6,$D$4:$D$323,0)) -> 494327.6 | O6: =LARGE($D$4:$D$323,2) -> 131186.44
A7: 4 | B7: ='Cleaned Data'!M5 -> 658920.3 | C7: ='Multiple Regression'!K36 -> 764831.24 | D7: ='Multiple Regression'!L36 -> -105910.94 | E7: ='Cleaned Data'!A5 -> STR-1001 | F7: ='Cleaned Data'!C5 -> East | G7: ='Cleaned Data'!D5 -> Residential | I7: =MATCH(O7,$D$4:$D$323,0) -> 202 | J7: =INDEX($E$4:$E$323,MATCH(O7,$D$4:$D$323,0)) -> STR-1051 | K7: =INDEX($F$4:$F$323,MATCH(O7,$D$4:$D$323,0)) -> East | L7: =INDEX($G$4:$G$323,MATCH(O7,$D$4:$D$323,0)) -> Airport | M7: =INDEX($B$4:$B$323,MATCH(O7,$D$4:$D$323,0)) -> 787715.51 | N7: =INDEX($C$4:$C$323,MATCH(O7,$D$4:$D$323,0)) -> 676769.7 | O7: =LARGE($D$4:$D$323,3) -> 110945.81
A8: 5 | B8: ='Cleaned Data'!M6 -> 741341.44 | C8: ='Multiple Regression'!K37 -> 766210.19 | D8: ='Multiple Regression'!L37 -> -24868.753 | E8: ='Cleaned Data'!A6 -> STR-1002 | F8: ='Cleaned Data'!C6 -> East | G8: ='Cleaned Data'!D6 -> High Street | I8: =MATCH(O8,$D$4:$D$323,0) -> 298 | J8: =INDEX($E$4:$E$323,MATCH(O8,$D$4:$D$323,0)) -> STR-1075 | K8: =INDEX($F$4:$F$323,MATCH(O8,$D$4:$D$323,0)) -> West | L8: =INDEX($G$4:$G$323,MATCH(O8,$D$4:$D$323,0)) -> High Street | M8: =INDEX($B$4:$B$323,MATCH(O8,$D$4:$D$323,0)) -> 763162.45 | N8: =INDEX($C$4:$C$323,MATCH(O8,$D$4:$D$323,0)) -> 660669.62 | O8: =LARGE($D$4:$D$323,4) -> 102492.83
A9: 6 | B9: ='Cleaned Data'!M7 -> 761835.34 | C9: ='Multiple Regression'!K38 -> 777521.77 | D9: ='Multiple Regression'!L38 -> -15686.426 | E9: ='Cleaned Data'!A7 -> STR-1002 | F9: ='Cleaned Data'!C7 -> East | G9: ='Cleaned Data'!D7 -> High Street | I9: =MATCH(O9,$D$4:$D$323,0) -> 8 | J9: =INDEX($E$4:$E$323,MATCH(O9,$D$4:$D$323,0)) -> STR-1002 | K9: =INDEX($F$4:$F$323,MATCH(O9,$D$4:$D$323,0)) -> East | L9: =INDEX($G$4:$G$323,MATCH(O9,$D$4:$D$323,0)) -> High Street | M9: =INDEX($B$4:$B$323,MATCH(O9,$D$4:$D$323,0)) -> 850164.26 | N9: =INDEX($C$4:$C$323,MATCH(O9,$D$4:$D$323,0)) -> 752354.33 | O9: =LARGE($D$4:$D$323,5) -> 97809.932
A10: 7 | B10: ='Cleaned Data'!M8 -> 806615.54 | C10: ='Multiple Regression'!K39 -> 797398.99 | D10: ='Multiple Regression'!L39 -> 9216.5509 | E10: ='Cleaned Data'!A8 -> STR-1002 | F10: ='Cleaned Data'!C8 -> East | G10: ='Cleaned Data'!D8 -> High Street
A11: 8 | B11: ='Cleaned Data'!M9 -> 850164.26 | C11: ='Multiple Regression'!K40 -> 752354.33 | D11: ='Multiple Regression'!L40 -> 97809.932 | E11: ='Cleaned Data'!A9 -> STR-1002 | F11: ='Cleaned Data'!C9 -> East | G11: ='Cleaned Data'!D9 -> High Street
A12: 9 | B12: ='Cleaned Data'!M10 -> 930581.7 | C12: ='Multiple Regression'!K41 -> 859273.56 | D12: ='Multiple Regression'!L41 -> 71308.141 | E12: ='Cleaned Data'!A10 -> STR-1003 | F12: ='Cleaned Data'!C10 -> North | G12: ='Cleaned Data'!D10 -> Airport | I12: TOP 5 LARGEST NEGATIVE RESIDUALS
A13: 10 | B13: ='Cleaned Data'!M11 -> 779010.94 | C13: ='Multiple Regression'!K42 -> 786719.06 | D13: ='Multiple Regression'!L42 -> -7708.1171 | E13: ='Cleaned Data'!A11 -> STR-1003 | F13: ='Cleaned Data'!C11 -> North | G13: ='Cleaned Data'!D11 -> Airport | I13: Observation | J13: Store_ID | K13: Region | L13: Store Type | M13: Actual Sales | N13: Predicted Sales | O13: Residual
A14: 11 | B14: ='Cleaned Data'!M12 -> 723060.76 | C14: ='Multiple Regression'!K43 -> 754397.67 | D14: ='Multiple Regression'!L43 -> -31336.915 | E14: ='Cleaned Data'!A12 -> STR-1003 | F14: ='Cleaned Data'!C12 -> North | G14: ='Cleaned Data'!D12 -> Airport | I14: =MATCH(O14,$D$4:$D$323,0) -> 45 | J14: =INDEX($E$4:$E$323,MATCH(O14,$D$4:$D$323,0)) -> STR-1012 | K14: =INDEX($F$4:$F$323,MATCH(O14,$D$4:$D$323,0)) -> West | L14: =INDEX($G$4:$G$323,MATCH(O14,$D$4:$D$323,0)) -> Residential | M14: =INDEX($B$4:$B$323,MATCH(O14,$D$4:$D$323,0)) -> 595467.6 | N14: =INDEX($C$4:$C$323,MATCH(O14,$D$4:$D$323,0)) -> 740179.86 | O14: =SMALL($D$4:$D$323,1) -> -144712.26
A15: 12 | B15: ='Cleaned Data'!M13 -> 910791.94 | C15: ='Multiple Regression'!K44 -> 854601.91 | D15: ='Multiple Regression'!L44 -> 56190.027 | E15: ='Cleaned Data'!A13 -> STR-1003 | F15: ='Cleaned Data'!C13 -> North | G15: ='Cleaned Data'!D13 -> Airport | I15: =MATCH(O15,$D$4:$D$323,0) -> 67 | J15: =INDEX($E$4:$E$323,MATCH(O15,$D$4:$D$323,0)) -> STR-1017 | K15: =INDEX($F$4:$F$323,MATCH(O15,$D$4:$D$323,0)) -> West | L15: =INDEX($G$4:$G$323,MATCH(O15,$D$4:$D$323,0)) -> High Street | M15: =INDEX($B$4:$B$323,MATCH(O15,$D$4:$D$323,0)) -> 685379.08 | N15: =INDEX($C$4:$C$323,MATCH(O15,$D$4:$D$323,0)) -> 823060.65 | O15: =SMALL($D$4:$D$323,2) -> -137681.57
A16: 13 | B16: ='Cleaned Data'!M14 -> 922168.6 | C16: ='Multiple Regression'!K45 -> 908254.76 | D16: ='Multiple Regression'!L45 -> 13913.836 | E16: ='Cleaned Data'!A14 -> STR-1004 | F16: ='Cleaned Data'!C14 -> East | G16: ='Cleaned Data'!D14 -> Residential | I16: =MATCH(O16,$D$4:$D$323,0) -> 33 | J16: =INDEX($E$4:$E$323,MATCH(O16,$D$4:$D$323,0)) -> STR-1009 | K16: =INDEX($F$4:$F$323,MATCH(O16,$D$4:$D$323,0)) -> North | L16: =INDEX($G$4:$G$323,MATCH(O16,$D$4:$D$323,0)) -> Residential | M16: =INDEX($B$4:$B$323,MATCH(O16,$D$4:$D$323,0)) -> 641865.03 | N16: =INDEX($C$4:$C$323,MATCH(O16,$D$4:$D$323,0)) -> 770451.97 | O16: =SMALL($D$4:$D$323,3) -> -128586.94
A17: 14 | B17: ='Cleaned Data'!M15 -> 726606.28 | C17: ='Multiple Regression'!K46 -> 784098.5 | D17: ='Multiple Regression'!L46 -> -57492.224 | E17: ='Cleaned Data'!A15 -> STR-1004 | F17: ='Cleaned Data'!C15 -> East | G17: ='Cleaned Data'!D15 -> Residential | I17: =MATCH(O17,$D$4:$D$323,0) -> 137 | J17: =INDEX($E$4:$E$323,MATCH(O17,$D$4:$D$323,0)) -> STR-1035 | K17: =INDEX($F$4:$F$323,MATCH(O17,$D$4:$D$323,0)) -> South | L17: =INDEX($G$4:$G$323,MATCH(O17,$D$4:$D$323,0)) -> Residential | M17: =INDEX($B$4:$B$323,MATCH(O17,$D$4:$D$323,0)) -> 633638.03 | N17: =INDEX($C$4:$C$323,MATCH(O17,$D$4:$D$323,0)) -> 753603.83 | O17: =SMALL($D$4:$D$323,4) -> -119965.8
A18: 15 | B18: ='Cleaned Data'!M16 -> 746501.09 | C18: ='Multiple Regression'!K47 -> 752597.74 | D18: ='Multiple Regression'!L47 -> -6096.652 | E18: ='Cleaned Data'!A16 -> STR-1004 | F18: ='Cleaned Data'!C16 -> East | G18: ='Cleaned Data'!D16 -> Residential | I18: =MATCH(O18,$D$4:$D$323,0) -> 306 | J18: =INDEX($E$4:$E$323,MATCH(O18,$D$4:$D$323,0)) -> STR-1077 | K18: =INDEX($F$4:$F$323,MATCH(O18,$D$4:$D$323,0)) -> South | L18: =INDEX($G$4:$G$323,MATCH(O18,$D$4:$D$323,0)) -> Residential | M18: =INDEX($B$4:$B$323,MATCH(O18,$D$4:$D$323,0)) -> 538376 | N18: =INDEX($C$4:$C$323,MATCH(O18,$D$4:$D$323,0)) -> 654685.64 | O18: =SMALL($D$4:$D$323,5) -> -116309.64
A19: 16 | B19: ='Cleaned Data'!M17 -> 834017.02 | C19: ='Multiple Regression'!K48 -> 836946.92 | D19: ='Multiple Regression'!L48 -> -2929.9021 | E19: ='Cleaned Data'!A17 -> STR-1004 | F19: ='Cleaned Data'!C17 -> East | G19: ='Cleaned Data'!D17 -> Residential
A20: 17 | B20: ='Cleaned Data'!M18 -> 666152.52 | C20: ='Multiple Regression'!K49 -> 692109.01 | D20: ='Multiple Regression'!L49 -> -25956.489 | E20: ='Cleaned Data'!A18 -> STR-1005 | F20: ='Cleaned Data'!C18 -> South | G20: ='Cleaned Data'!D18 -> Residential
A21: 18 | B21: ='Cleaned Data'!M19 -> 573155.19 | C21: ='Multiple Regression'!K50 -> 608113.93 | D21: ='Multiple Regression'!L50 -> -34958.741 | E21: ='Cleaned Data'!A19 -> STR-1005 | F21: ='Cleaned Data'!C19 -> South | G21: ='Cleaned Data'!D19 -> Residential
A22: 19 | B22: ='Cleaned Data'!M20 -> 666573.2 | C22: ='Multiple Regression'!K51 -> 681740.46 | D22: ='Multiple Regression'!L51 -> -15167.256 | E22: ='Cleaned Data'!A20 -> STR-1005 | F22: ='Cleaned Data'!C20 -> South | G22: ='Cleaned Data'!D20 -> Residential
A23: 20 | B23: ='Cleaned Data'!M21 -> 591619.95 | C23: ='Multiple Regression'!K52 -> 621825.84 | D23: ='Multiple Regression'!L52 -> -30205.889 | E23: ='Cleaned Data'!A21 -> STR-1005 | F23: ='Cleaned Data'!C21 -> South | G23: ='Cleaned Data'!D21 -> Residential
A24: 21 | B24: ='Cleaned Data'!M22 -> 415721.82 | C24: ='Multiple Regression'!K53 -> 521596.5 | D24: ='Multiple Regression'!L53 -> -105874.68 | E24: ='Cleaned Data'!A22 -> STR-1006 | F24: ='Cleaned Data'!C22 -> North | G24: ='Cleaned Data'!D22 -> Residential
A25: 22 | B25: ='Cleaned Data'!M23 -> 491905.13 | C25: ='Multiple Regression'!K54 -> 502343.56 | D25: ='Multiple Regression'!L54 -> -10438.426 | E25: ='Cleaned Data'!A23 -> STR-1006 | F25: ='Cleaned Data'!C23 -> North | G25: ='Cleaned Data'!D23 -> Residential
A26: 23 | B26: ='Cleaned Data'!M24 -> 555929.4 | C26: ='Multiple Regression'!K55 -> 572515.54 | D26: ='Multiple Regression'!L55 -> -16586.144 | E26: ='Cleaned Data'!A24 -> STR-1006 | F26: ='Cleaned Data'!C24 -> North | G26: ='Cleaned Data'!D24 -> Residential
A27: 24 | B27: ='Cleaned Data'!M25 -> 565810.99 | C27: ='Multiple Regression'!K56 -> 558445.9 | D27: ='Multiple Regression'!L56 -> 7365.0855 | E27: ='Cleaned Data'!A25 -> STR-1006 | F27: ='Cleaned Data'!C25 -> North | G27: ='Cleaned Data'!D25 -> Residential
A28: 25 | B28: ='Cleaned Data'!M26 -> 811771.14 | C28: ='Multiple Regression'!K57 -> 815025.68 | D28: ='Multiple Regression'!L57 -> -3254.5411 | E28: ='Cleaned Data'!A26 -> STR-1007 | F28: ='Cleaned Data'!C26 -> West | G28: ='Cleaned Data'!D26 -> Mall
A29: 26 | B29: ='Cleaned Data'!M27 -> 800451.94 | C29: ='Multiple Regression'!K58 -> 900690.68 | D29: ='Multiple Regression'!L58 -> -100238.74 | E29: ='Cleaned Data'!A27 -> STR-1007 | F29: ='Cleaned Data'!C27 -> West | G29: ='Cleaned Data'!D27 -> Mall
A30: 27 | B30: ='Cleaned Data'!M28 -> 783672.82 | C30: ='Multiple Regression'!K59 -> 781190.83 | D30: ='Multiple Regression'!L59 -> 2481.9939 | E30: ='Cleaned Data'!A28 -> STR-1007 | F30: ='Cleaned Data'!C28 -> West | G30: ='Cleaned Data'!D28 -> Mall
... A323: 320 | B323: ='Cleaned Data'!M321 -> 559660.84 | C323: ='Multiple Regression'!K352 -> 611901.56 | D323: ='Multiple Regression'!L352 -> -52240.72 | E323: ='Cleaned Data'!A321 -> STR-1080 | F323: ='Cleaned Data'!C321 -> East | G323: ='Cleaned Data'!D321 -> Residential
